<?xml version="1.0"?>
<sdf version="1.9">
  <model name="plantation_uav">
    <pose>0 0 1 0 0 0</pose>
    <self_collide>false</self_collide>

    <link name="base_link">
      <inertial>
        <mass>1.5</mass>
        <inertia>
          <ixx>0.0347563</ixx><ixy>0</ixy><ixz>0</ixz>
          <iyy>0.070</iyy><iyz>0</iyz><izz>0.0977</izz>
        </inertia>
      </inertial>
      <collision name="body_collision">
        <geometry><box><size>0.47 0.47 0.11</size></box></geometry>
      </collision>
      <visual name="x3_body_visual">
        <geometry>
          <mesh><scale>1 1 1</scale><uri>model://plantation_quadrotor/meshes/x3.dae</uri></mesh>
        </geometry>
      </visual>
    </link>

    <link name="zed2i_link">
      <pose relative_to="base_link">0.12 0 0.02 0 0 0</pose>
      <inertial><mass>0.09</mass><inertia><ixx>0.00008</ixx><iyy>0.00008</iyy><izz>0.00008</izz></inertia></inertial>
      <visual name="zed2i_body">
        <geometry><box><size>0.030 0.175 0.033</size></box></geometry>
        <material><ambient>0.15 0.16 0.17 1</ambient><diffuse>0.20 0.21 0.22 1</diffuse></material>
      </visual>
      <sensor name="zed2i_left_camera" type="camera">
        <pose>0.02 0.06 0 0 0 0</pose>
        <topic>/plantation_uav/zed2i/left/image_rect_color</topic>
        <always_on>true</always_on>
        <update_rate>30</update_rate>
        <camera><horizontal_fov>1.3962634</horizontal_fov><image><width>640</width><height>480</height></image><clip><near>0.05</near><far>80</far></clip></camera>
      </sensor>
      <sensor name="zed2i_depth_camera" type="rgbd_camera">
        <pose>0.03 0 0 0 0 0</pose>
        <topic>/plantation_uav/zed2i/depth</topic>
        <always_on>true</always_on>
        <update_rate>30</update_rate>
        <camera><horizontal_fov>1.3962634</horizontal_fov><image><width>640</width><height>480</height></image><clip><near>0.12</near><far>15</far></clip></camera>
      </sensor>
    </link>
    <joint name="zed2i_joint" type="fixed"><parent>base_link</parent><child>zed2i_link</child></joint>

    <link name="range_link">
      <pose relative_to="base_link">0 0 -0.08 0 1.57079632679 0</pose>
      <inertial><mass>0.02</mass><inertia><ixx>0.00001</ixx><iyy>0.00001</iyy><izz>0.00001</izz></inertia></inertial>
      <sensor name="downward_lidar" type="gpu_lidar">
        <topic>/plantation_uav/range</topic>
        <always_on>true</always_on>
        <update_rate>50</update_rate>
        <lidar><scan><horizontal><samples>1</samples></horizontal><vertical><samples>1</samples></vertical></scan><range><min>0.08</min><max>20</max></range></lidar>
      </sensor>
    </link>
    <joint name="range_joint" type="fixed"><parent>base_link</parent><child>range_link</child></joint>

    <link name='imu_link'>
      <inertial>
        <pose>0 0 0 0 0 0</pose>
        <mass>0.15</mass>
        <inertia><ixx>0.00001</ixx><iyy>0.00002</iyy><izz>0.00002</izz></inertia>
      </inertial>
      <sensor name="imu_sensor" type="imu">
        <gz_frame_id>imu_link</gz_frame_id>
        <pose degrees="true">0 0 0 180 0 0</pose>
        <always_on>1</always_on>
        <update_rate>1000.0</update_rate>
      </sensor>
    </link>
    <joint name='imu_joint' type='revolute'>
      <child>imu_link</child>
      <parent>base_link</parent>
      <axis>
        <xyz>0 0 1</xyz>
        <limit><lower>0</lower><upper>0</upper><effort>0</effort><velocity>0</velocity></limit>
        <dynamics><damping>1.0</damping></dynamics>
      </axis>
    </joint>

    <link name="rotor_0">
      <pose relative_to="base_link">0.13 -0.22 0.023 0 0 0</pose>
      <inertial><mass>0.005</mass><inertia><ixx>9.75e-07</ixx><iyy>4.17041e-05</iyy><izz>4.26041e-05</izz></inertia></inertial>
      <visual name="visual"><geometry><mesh><scale>0.1 0.1 0.1</scale><uri>model://plantation_quadrotor/meshes/propeller_ccw.dae</uri></mesh></geometry></visual>
    </link>
    <link name="rotor_1">
      <pose relative_to="base_link">-0.13 0.20 0.023 0 0 0</pose>
      <inertial><mass>0.005</mass><inertia><ixx>9.75e-07</ixx><iyy>4.17041e-05</iyy><izz>4.26041e-05</izz></inertia></inertial>
      <visual name="visual"><geometry><mesh><scale>0.1 0.1 0.1</scale><uri>model://plantation_quadrotor/meshes/propeller_ccw.dae</uri></mesh></geometry></visual>
    </link>
    <link name="rotor_2">
      <pose relative_to="base_link">0.13 0.22 0.023 0 0 0</pose>
      <inertial><mass>0.005</mass><inertia><ixx>9.75e-07</ixx><iyy>4.17041e-05</iyy><izz>4.26041e-05</izz></inertia></inertial>
      <visual name="visual"><geometry><mesh><scale>0.1 0.1 0.1</scale><uri>model://plantation_quadrotor/meshes/propeller_cw.dae</uri></mesh></geometry></visual>
    </link>
    <link name="rotor_3">
      <pose relative_to="base_link">-0.13 -0.20 0.023 0 0 0</pose>
      <inertial><mass>0.005</mass><inertia><ixx>9.75e-07</ixx><iyy>4.17041e-05</iyy><izz>4.26041e-05</izz></inertia></inertial>
      <visual name="visual"><geometry><mesh><scale>0.1 0.1 0.1</scale><uri>model://plantation_quadrotor/meshes/propeller_cw.dae</uri></mesh></geometry></visual>
    </link>

    <joint name="rotor_0_joint" type="revolute">
      <parent>base_link</parent><child>rotor_0</child>
      <axis><xyz>0 0 1</xyz><limit><lower>-1e16</lower><upper>1e16</upper></limit><dynamics><damping>0.004</damping></dynamics></axis>
    </joint>
    <joint name="rotor_1_joint" type="revolute">
      <parent>base_link</parent><child>rotor_1</child>
      <axis><xyz>0 0 1</xyz><limit><lower>-1e16</lower><upper>1e16</upper></limit><dynamics><damping>0.004</damping></dynamics></axis>
    </joint>
    <joint name="rotor_2_joint" type="revolute">
      <parent>base_link</parent><child>rotor_2</child>
      <axis><xyz>0 0 1</xyz><limit><lower>-1e16</lower><upper>1e16</upper></limit><dynamics><damping>0.004</damping></dynamics></axis>
    </joint>
    <joint name="rotor_3_joint" type="revolute">
      <parent>base_link</parent><child>rotor_3</child>
      <axis><xyz>0 0 1</xyz><limit><lower>-1e16</lower><upper>1e16</upper></limit><dynamics><damping>0.004</damping></dynamics></axis>
    </joint>

    <plugin filename="gz-sim-apply-joint-force-system" name="gz::sim::systems::ApplyJointForce">
      <joint_name>rotor_0_joint</joint_name>
    </plugin>
    <plugin filename="gz-sim-apply-joint-force-system" name="gz::sim::systems::ApplyJointForce">
      <joint_name>rotor_1_joint</joint_name>
    </plugin>
    <plugin filename="gz-sim-apply-joint-force-system" name="gz::sim::systems::ApplyJointForce">
      <joint_name>rotor_2_joint</joint_name>
    </plugin>
    <plugin filename="gz-sim-apply-joint-force-system" name="gz::sim::systems::ApplyJointForce">
      <joint_name>rotor_3_joint</joint_name>
    </plugin>

    <plugin name="ArduPilotPlugin" filename="ArduPilotPlugin">
      <fdm_addr>127.0.0.1</fdm_addr>
      <fdm_port_in>9002</fdm_port_in>
      <fdm_port_out>9003</fdm_port_out>
      <connectionTimeoutMaxCount>5</connectionTimeoutMaxCount>
      <lock_step>1</lock_step>
      <no_time_sync>1</no_time_sync>

      <modelXYZToAirplaneXForwardZDown degrees="true">0 0 0 180 0 0</modelXYZToAirplaneXForwardZDown>
      <gazeboXYZToNED degrees="true">0 0 0 180 0 90</gazeboXYZToNED>

      <imuName>plantation_uav::imu_link::imu_sensor</imuName>

      <control channel="0">
        <jointName>rotor_0_joint</jointName>
        <useForce>1</useForce>
        <multiplier>838</multiplier>
        <offset>0</offset>
        <servo_min>1100</servo_min>
        <servo_max>1900</servo_max>
        <type>VELOCITY</type>
        <p_gain>0.20</p_gain>
        <i_gain>0</i_gain>
        <d_gain>0</d_gain>
        <i_max>0</i_max>
        <i_min>0</i_min>
        <cmd_max>2.5</cmd_max>
        <cmd_min>-2.5</cmd_min>
        <controlVelocitySlowdownSim>1</controlVelocitySlowdownSim>
      </control>
      <control channel="1">
        <jointName>rotor_1_joint</jointName>
        <useForce>1</useForce>
        <multiplier>838</multiplier>
        <offset>0</offset>
        <servo_min>1100</servo_min>
        <servo_max>1900</servo_max>
        <type>VELOCITY</type>
        <p_gain>0.20</p_gain>
        <i_gain>0</i_gain>
        <d_gain>0</d_gain>
        <i_max>0</i_max>
        <i_min>0</i_min>
        <cmd_max>2.5</cmd_max>
        <cmd_min>-2.5</cmd_min>
        <controlVelocitySlowdownSim>1</controlVelocitySlowdownSim>
      </control>
      <control channel="2">
        <jointName>rotor_2_joint</jointName>
        <useForce>1</useForce>
        <multiplier>-838</multiplier>
        <offset>0</offset>
        <servo_min>1100</servo_min>
        <servo_max>1900</servo_max>
        <type>VELOCITY</type>
        <p_gain>0.20</p_gain>
        <i_gain>0</i_gain>
        <d_gain>0</d_gain>
        <i_max>0</i_max>
        <i_min>0</i_min>
        <cmd_max>2.5</cmd_max>
        <cmd_min>-2.5</cmd_min>
        <controlVelocitySlowdownSim>1</controlVelocitySlowdownSim>
      </control>
      <control channel="3">
        <jointName>rotor_3_joint</jointName>
        <useForce>1</useForce>
        <multiplier>-838</multiplier>
        <offset>0</offset>
        <servo_min>1100</servo_min>
        <servo_max>1900</servo_max>
        <type>VELOCITY</type>
        <p_gain>0.20</p_gain>
        <i_gain>0</i_gain>
        <d_gain>0</d_gain>
        <i_max>0</i_max>
        <i_min>0</i_min>
        <cmd_max>2.5</cmd_max>
        <cmd_min>-2.5</cmd_min>
        <controlVelocitySlowdownSim>1</controlVelocitySlowdownSim>
      </control>
    </plugin>
  </model>
</sdf>